<!DOCTYPE html>
<html lang="en">
<head>
    <meta charset="UTF-8">
    <meta http-equiv="X-UA-Compatible" content="IE=edge">
    <meta name="viewport" content="width=device-width, initial-scale=1.0">
    <title>Document</title>
</head>
<body>
    <!-- https://es6.ruanyifeng.com/#docs/promise -->
    <!-- https://segmentfault.com/a/1190000011652907 -->
    <!-- 1、
    Promise 是一个容器，存放着某个未来才会结束的事件（通常是一个异步操作
    从语法上看promise是一个可以获取异步操作消息的 对象
     -->
    
    Promise对象特点
    1、 对象的状态不受外界影响。Promise对象代表一个异步操作，有三种状态pending(进行中)，fulfilled(成功),rejected(失败)
    只有异步操作的结果可以决定当前是哪一种状态，其他操作都无法改变状态
    2、一旦状态改变就不会再变。Promise对象的状态改变只有两种可能，从pending到fulfilled和从pending到rejected
    一旦状态改变了，就不会再变 称为resolved(已定型)，如果改变已经发生了，再对其添加回调函数，也会立即得到这个结果，
    这与事件（Event）完全不同，事件的特点是，如果你错过了它，再去监听，是得不到结果的。
    
    基本用法
    Promise对象是一个构造函数，用来生成Promise实例
        const promise = new Promise(function(resolve, reject) {
            // ... some code
        
            if (/* 异步操作成功 */){
            resolve(value);//异步操作成功时调用，resolve函数将promise对象状态从pending变为resolved，并将异步操作的结果作为参数传出，传到then方法中
            } else {
            reject(error);//异步操作失败时调用，reject函数将promise对象状态从pending变为reject,并将异步操作的结果作为参数传出，传到then方法中
            }
        });
    Promise实例生成以后，可以用then方法分别指定resolved状态和rejected状态的回调函数。
        promise.then(function(value) {
            // success
        }, function(error) {
            // failure
        });
        then方法可以接受两个回调函数作为参数。
        第一个回调函数是Promise对象的状态变为resolved时调用，
        第二个回调函数是Promise对象的状态变为rejected时调用。
        这两个函数都是可选的，不一定要提供。它们都接受Promise对象传出的值作为参数。
        
        <script>
        // <!-- for example1 -->
            // qry:function(event){
            //     return new Promise((resolve,reject) => {
            //     // fetch是封装的一个请求函数
            //     this.fetch('billFile/qry',{
            //         data:params
            //     }).then(res => {
            //         // 请求成功
            //         if(res.resultCode == '0000000') {
            //             resolve();
            //             //接下来的处理代码
            //         }else{
            //             // 请求失败
            //             reject()
            //         }
            //     })
            // })
            // }
            let promiseExample = new Promise((resolve , reject) => {
                // promise新建后立即执行
                console.log('promise对象执行')
                let success = true
                if(success){
                    resolve()
                }else{
                    reject()
                }
                // resolve()                                                                                                
                // reject()
            })


            promiseExample.then(() => {
                // then方法指定的回调函数会在当前脚本所有同步任务执行完才会执行，所以resolve最后输出
                console.log('resolved')
            },() => {
                // 当状态是rejected的时候会进入then方法的第二个函数，否则会进入第一个
                console.log('rejected')
            })
            console.log('HI')
            // 所以执行顺序是1、console.log('promise对象执行') 2、console.log('HI') 3、console.log('resolve')


            // qry函数调用时，会返回一个Promise对象，这个对象会发送一个请求，请求成功后，Promise对象状态变为resolved，就会调用then中的函数

        </script>
        <script>
            console.log('---------------------------')
            var promise1 = new Promise(function(resolve, reject) {
                // 2秒后置为接收状态
                setTimeout(function() {
                    resolve('success');
                }, 2000);
                });

                promise1.then(function(data) {
                    console.log(data); // success
                    // return data 这样就会出现 链式调用:success
                    }, function(err) {
                    console.log(err); // 不执行
                    }).then(function(data) {
                    // 上一步的then()方法没有返回值
                    console.log('链式调用：' + data); // 链式调用：undefined 
                    }).then(function(data) {
                    // ....
                });

                var promise2 = new Promise(function(resolve, reject) {
                    // 1秒后置为接收状态
                    setTimeout(function() {
                        resolve('success');
                    }, 1000);
                    });

                    promise2
                    .then(function(data) {
                        // 上一个then()调用了resolve，置为fulfilled态
                        console.log('第一个then');
                        console.log(data);
                        // 这里的返回值会传到then方法的函数中
                        // 这里因为上面调用了resolve，所以是fulfilled状态，返回的数据也会到下一个then的resolve函数中，即then的第一个函数
                        return data;
                    })
                    .then(function(data) {
                        // 此时这里的状态也是fulfilled, 因为上一步返回了2
                        console.log('第二个then');
                        console.log(data);  // 2

                        return new Promise(function(resolve, reject) {
                        reject('把状态置为rejected error'); // 返回一个rejected的Promise实例
                        });
                    }, function(err) {
                        // error
                    })
                    .then(function(data) {
                        /* 这里不运行 */

                        // 当调用reject()函数就会跳过then方法的第一个函数
                        console.log('第三个then');
                        console.log(data);
                        // ....
                    }, function(err) {
                        // error回调
                        // 此时这里的状态也是fulfilled, 因为上一步使用了reject()来返回值
                        console.log('出错：' + err); // 出错：把状态置为rejected error
                    })
                    .then(function(data) {
                        // 没有明确指定返回值，默认返回fulfilled
                        console.log('这里是fulfilled态');
                    });
        </script>
        <script>
            console.log('---------------------------')
            // catch()方法和then()方法一样，都会返回一个新的Promise对象，它主要用于捕获异步操作时出现的异常。
            // 因此，我们通常省略then()方法的第二个参数，把错误处理控制权转交给其后面的catch()函数，如下：
            var promise3 = new Promise(function(resolve, reject) {
            setTimeout(function() {
                reject('reject');
            }, 2000);
            });
            // 当promise状态为rejected的时候，可以用catch()来获取抛出的异常，catch获取的参数就是reject()中传入的参数
            promise3.then(function(data) {
            console.log('这里是fulfilled状态'); // 这里不会触发
            // ...
            }).catch(function(err) {
            // 最后的catch()方法可以捕获在这一条Promise链上的异常
            console.log('出错：' + err); // 出错：reject
            });
        </script>
        <script>
            // Promise.all()接受一个参数，必须是可迭代对象
            // 用来处理一些并发的异步操作，即结果互不干扰，但是又需要异步执行，且它只有两种状态，成功或失败
            // 当它接受参数的所有值都为fulfilled时，它才会变成fuifilled，否则为rejected
            // 成功调用后返回一个数组，数组的值是有序的，按照传入参数的数组的值返回后的结果

            // 值为fulfilled状态的情况
            var arr = [1, 2, 3];
            var promises = arr.map(function(e) {
            return new Promise(function(resolve, reject) {
                resolve(e * 5);
            });
            });

            Promise.all(promises).then(function(data) {
                // 有序输出
            console.log(data); // [5, 10, 15]
            console.log(arr); // [1, 2, 3]
            });

            // 置为rejected状态的情况
            var arr = [1, 2, 3];
            var promises2 = arr.map(function(e) {
            return new Promise(function(resolve, reject) {
                if (e === 3) {
                reject('rejected');
                }
                resolve(e * 5);
            });
            });

            Promise.all(promises2).then(function(data) {
            // 这里不会执行
            console.log(data);
            console.log(arr);
            }).catch(function(err) {
            console.log(err); // rejected
            });
        </script>
        <script>
            // Promise.race()和Promise.all()类似，都接收一个可以迭代的参数，
            // 但是不同之处是Promise.race()的状态变化不是全部受参数内的状态影响，
            // 一旦参数内有一个值的状态发生的改变，那么该Promise的状态就是改变的状态。
            // 就跟race单词的字面意思一样，谁跑的快谁赢。如下：
            var p1 = new Promise(function(resolve, reject) {
            setTimeout(resolve, 300, 'p1 doned');
            });

            var p2 = new Promise(function(resolve, reject) {
            setTimeout(resolve, 50, 'p2 doned');
            });

            var p3 = new Promise(function(resolve, reject) {
            setTimeout(reject, 100, 'p3 rejected');
            });

            Promise.race([p1, p2, p3]).then(function(data) {
            // 显然p2更快，所以状态变成了fulfilled
            // 如果p3更快，那么状态就会变成rejected
            console.log(data); // p2 doned
            }).catch(function(err) {
            console.log(err); // 不执行
            });
        </script>
        <script>
            // Promise.resolve()接受一个参数值，可以是普通的值，具有then()方法的对象和Promise实例。
            // 正常情况下，它返回一个Promise对象，状态为fulfilled。
            // 但是，当解析时发生错误时，返回的Promise对象将会置为rejected态。如下：
            // 参数为普通值
            var p4 = Promise.resolve(5);
            p4.then(function(data) {
            console.log(data); // 5
            });


            // 参数为含有then()方法的对象
            var obj = {
            then: function() {
                console.log('obj 里面的then()方法');
            }
            };

            var p5 = Promise.resolve(obj);
            p5.then(function(data) {
            // 这里的值时obj方法里面返回的值
            console.log(data); // obj 里面的then()方法
            });


            // 参数为Promise实例
            var p6 = Promise.resolve(7);
            var p7 = Promise.resolve(p6);

            p7.then(function(data) {
            // 这里的值时Promise实例返回的值
            console.log(data); // 7
            });

            // 参数为Promise实例,但参数是rejected态
            var p8 = Promise.reject(8);
            var p9 = Promise.resolve(p8);

            p9.then(function(data) {
            // 这里的值时Promise实例返回的值
            console.log('fulfilled:'+ data); // 不执行
            }).catch(function(err) {
            console.log('rejected:' + err); // rejected: 8
            });
        </script>
        <script>
            // Promise.reject()和Promise.resolve()正好相反，它接收一个参数值reason，即发生异常的原因。
            // 此时返回的Promise对象将会置为rejected态。如下：
            var p10 = Promise.reject('手动拒绝');
            p10.then(function(data) {
            console.log(data); // 这里不会执行，因为是rejected态
            }).catch(function(err) {
            console.log(err); // 手动拒绝
            }).then(function(data) {
            // 不受上一级影响
            console.log('状态：fulfilled'); // 状态：fulfilled
            });


            // 总之，除非Promise.then()方法内部抛出异常或者是明确置为rejected态，
            // 否则它返回的Promise的状态都是fulfilled态，即完成态，并且它的状态不受它的上一级的状态的影响。
            console.log('还需要再看看')
        </script>
</body>
</html>